Workbook

Sheet Bracket
B2: GROUP STAGE | J2: ROUND OF 32 | O2: ROUND OF 16 | T2: QUARTER-FINALS | Y2: SEMI-FINALS | AD2: FINALS
B4: GROUP A
B5: MEXICO | C5: SOUTH AFRICA | D5: 2 | E5: 0 | F5: 1A | G5: {=IF(SUMPRODUCT((LEN($D$5:$D$10)>0)*(LEN($E$5:$E$10)>0))=0,"",IFERROR(INDEX($AN$5:$AN$8,MATCH(LARGE($AP$5:$AP$8,1),$AP$5:$AP$8,0)),""))} -> MEXICO | H5: {=IF(SUMPRODUCT((LEN($D$5:$D$10)>0)*(LEN($E$5:$E$10)>0))=0,"",IFERROR(INDEX($AO$5:$AO$8,MATCH(LARGE($AP$5:$AP$8,1),$AP$5:$AP$8,0)),""))} -> 5 | J5: 1E | K5: =_xlfn.XLOOKUP(J5,$F$5:$F$85,$G$5:$G$85, "") -> GERMANY | L5: 1 | M5: T1 | AN5: =B5 -> MEXICO | AO5: {=3*SUMPRODUCT(($B$5:$B$10=AN5)*($D$5:$D$10>$E$5:$E$10))+3*SUMPRODUCT(($C$5:$C$10=AN5)*($E$5:$E$10>$D$5:$D$10))+SUMPRODUCT((($B$5:$B$10=AN5)+($C$5:$C$10=AN5))*($D$5:$D$10=$E$5:$E$10)*(LEN($D$5:$D$10)>0))} -> 5 | AP5: =AO5*1000000+(AQ5-AR5)*1000+AQ5*10-0 -> 5002050 | AQ5: {=SUMPRODUCT(($B$5:$B$10=AN5)*$D$5:$D$10)+SUMPRODUCT(($C$5:$C$10=AN5)*$E$5:$E$10)} -> 5 | AR5: {=SUMPRODUCT(($B$5:$B$10=AN5)*$E$5:$E$10)+SUMPRODUCT(($C$5:$C$10=AN5)*$D$5:$D$10)} -> 3 | AT5: 3RD | AU5: TEAM | AV5: KEY | AW5: RANK
B6: SOUTH KOREA | C6: CZECHIA | D6: 1 | E6: 2 | F6: 2A | G6: {=IF(SUMPRODUCT((LEN($D$5:$D$10)>0)*(LEN($E$5:$E$10)>0))=0,"",IFERROR(INDEX($AN$5:$AN$8,MATCH(LARGE($AP$5:$AP$8,2),$AP$5:$AP$8,0)),""))} -> CZECHIA | H6: {=IF(SUMPRODUCT((LEN($D$5:$D$10)>0)*(LEN($E$5:$E$10)>0))=0,"",IFERROR(INDEX($AO$5:$AO$8,MATCH(LARGE($AP$5:$AP$8,2),$AP$5:$AP$8,0)),""))} -> 5 | J6: =AU26 -> 3C | K6: =_xlfn.XLOOKUP(J6,$F$5:$F$85,$G$5:$G$85, "") -> MOROCCO | AN6: =C5 -> SOUTH AFRICA | AO6: {=3*SUMPRODUCT(($B$5:$B$10=AN6)*($D$5:$D$10>$E$5:$E$10))+3*SUMPRODUCT(($C$5:$C$10=AN6)*($E$5:$E$10>$D$5:$D$10))+SUMPRODUCT((($B$5:$B$10=AN6)+($C$5:$C$10=AN6))*($D$5:$D$10=$E$5:$E$10)*(LEN($D$5:$D$10)>0))} -> 1 | AP6: =AO6*1000000+(AQ6-AR6)*1000+AQ6*10-1 -> 997029 | AQ6: {=SUMPRODUCT(($B$5:$B$10=AN6)*$D$5:$D$10)+SUMPRODUCT(($C$5:$C$10=AN6)*$E$5:$E$10)} -> 3 | AR6: {=SUMPRODUCT(($B$5:$B$10=AN6)*$E$5:$E$10)+SUMPRODUCT(($C$5:$C$10=AN6)*$D$5:$D$10)} -> 6 | AT6: 3A | AU6: =_xlfn.XLOOKUP(AT6,$F$5:$F$85,$G$5:$G$85,"") -> SOUTH KOREA | AV6: {=IF(SUMPRODUCT((LEN($D$5:$D$10)>0)*(LEN($E$5:$E$10)>0))=0,"",LARGE($AP$5:$AP$8,3)-0)} -> 4000058 | AW6: =IF(AV6="","",RANK(AV6,$AV$6:$AV$17,0)) -> 3
B7: CZECHIA | C7: SOUTH AFRICA | D7: 1 | E7: 1 | F7: 3A | G7: {=IF(SUMPRODUCT((LEN($D$5:$D$10)>0)*(LEN($E$5:$E$10)>0))=0,"",IFERROR(INDEX($AN$5:$AN$8,MATCH(LARGE($AP$5:$AP$8,3),$AP$5:$AP$8,0)),""))} -> SOUTH KOREA | H7: {=IF(SUMPRODUCT((LEN($D$5:$D$10)>0)*(LEN($E$5:$E$10)>0))=0,"",IFERROR(INDEX($AO$5:$AO$8,MATCH(LARGE($AP$5:$AP$8,3),$AP$5:$AP$8,0)),""))} -> 4 | O7: T1 | P7: =IF(L5="","",IF(L5=1, K5, K6)) -> GERMANY | Q7: 2 | R7: Q1 | AN7: =B6 -> SOUTH KOREA | AO7: {=3*SUMPRODUCT(($B$5:$B$10=AN7)*($D$5:$D$10>$E$5:$E$10))+3*SUMPRODUCT(($C$5:$C$10=AN7)*($E$5:$E$10>$D$5:$D$10))+SUMPRODUCT((($B$5:$B$10=AN7)+($C$5:$C$10=AN7))*($D$5:$D$10=$E$5:$E$10)*(LEN($D$5:$D$10)>0))} -> 4 | AP7: =AO7*1000000+(AQ7-AR7)*1000+AQ7*10-2 -> 4000058 | AQ7: {=SUMPRODUCT(($B$5:$B$10=AN7)*$D$5:$D$10)+SUMPRODUCT(($C$5:$C$10=AN7)*$E$5:$E$10)} -> 6 | AR7: {=SUMPRODUCT(($B$5:$B$10=AN7)*$E$5:$E$10)+SUMPRODUCT(($C$5:$C$10=AN7)*$D$5:$D$10)} -> 6 | AT7: 3B | AU7: =_xlfn.XLOOKUP(AT7,$F$5:$F$85,$G$5:$G$85,"") -> BOSNIA H. | AV7: {=IF(SUMPRODUCT((LEN($D$12:$D$17)>0)*(LEN($E$12:$E$17)>0))=0,"",LARGE($AP$12:$AP$15,3)-1)} -> 4000028 | AW7: =IF(AV7="","",RANK(AV7,$AV$6:$AV$17,0)) -> 4
B8: MEXICO | C8: SOUTH KOREA | D8: 2 | E8: 2 | F8: 4A | G8: {=IF(SUMPRODUCT((LEN($D$5:$D$10)>0)*(LEN($E$5:$E$10)>0))=0,"",IFERROR(INDEX($AN$5:$AN$8,MATCH(LARGE($AP$5:$AP$8,4),$AP$5:$AP$8,0)),""))} -> SOUTH AFRICA | H8: {=IF(SUMPRODUCT((LEN($D$5:$D$10)>0)*(LEN($E$5:$E$10)>0))=0,"",IFERROR(INDEX($AO$5:$AO$8,MATCH(LARGE($AP$5:$AP$8,4),$AP$5:$AP$8,0)),""))} -> 1 | O8: T2 | P8: =IF(L9="","",IF(L9=1, K9, K10)) -> FRANCE | AN8: =C6 -> CZECHIA | AO8: {=3*SUMPRODUCT(($B$5:$B$10=AN8)*($D$5:$D$10>$E$5:$E$10))+3*SUMPRODUCT(($C$5:$C$10=AN8)*($E$5:$E$10>$D$5:$D$10))+SUMPRODUCT((($B$5:$B$10=AN8)+($C$5:$C$10=AN8))*($D$5:$D$10=$E$5:$E$10)*(LEN($D$5:$D$10)>0))} -> 5 | AP8: =AO8*1000000+(AQ8-AR8)*1000+AQ8*10-3 -> 5001037 | AQ8: {=SUMPRODUCT(($B$5:$B$10=AN8)*$D$5:$D$10)+SUMPRODUCT(($C$5:$C$10=AN8)*$E$5:$E$10)} -> 4 | AR8: {=SUMPRODUCT(($B$5:$B$10=AN8)*$E$5:$E$10)+SUMPRODUCT(($C$5:$C$10=AN8)*$D$5:$D$10)} -> 3 | AT8: 3C | AU8: =_xlfn.XLOOKUP(AT8,$F$5:$F$85,$G$5:$G$85,"") -> MOROCCO | AV8: {=IF(SUMPRODUCT((LEN($D$19:$D$24)>0)*(LEN($E$19:$E$24)>0))=0,"",LARGE($AP$19:$AP$22,3)-2)} -> 4000067 | AW8: =IF(AV8="","",RANK(AV8,$AV$6:$AV$17,0)) -> 2
B9: CZECHIA | C9: MEXICO | D9: 1 | E9: 1 | J9: 1I | K9: =_xlfn.XLOOKUP(J9,$F$5:$F$85,$G$5:$G$85, "") -> FRANCE | L9: 1 | M9: T2 | AT9: 3D | AU9: =_xlfn.XLOOKUP(AT9,$F$5:$F$85,$G$5:$G$85,"") -> AUSTRALIA | AV9: {=IF(SUMPRODUCT((LEN($D$26:$D$31)>0)*(LEN($E$26:$E$31)>0))=0,"",LARGE($AP$26:$AP$29,3)-3)} -> 997015 | AW9: =IF(AV9="","",RANK(AV9,$AV$6:$AV$17,0)) -> 10
B10: SOUTH AFRICA | C10: SOUTH KOREA | D10: 2 | E10: 3 | J10: =AU28 -> 3G | K10: =_xlfn.XLOOKUP(J10,$F$5:$F$85,$G$5:$G$85, "") -> IRAN | AT10: 3E | AU10: =_xlfn.XLOOKUP(AT10,$F$5:$F$85,$G$5:$G$85,"") -> IVORY COAST | AV10: {=IF(SUMPRODUCT((LEN($D$33:$D$38)>0)*(LEN($E$33:$E$38)>0))=0,"",LARGE($AP$33:$AP$36,3)-4)} -> 2999034 | AW10: =IF(AV10="","",RANK(AV10,$AV$6:$AV$17,0)) -> 6
B11: GROUP B | T11: Q1 | U11: =IF(Q7="","",IF(Q7=1, P7, P8)) -> FRANCE | V11: 1 | W11: S1 | AT11: 3F | AU11: =_xlfn.XLOOKUP(AT11,$F$5:$F$85,$G$5:$G$85,"") -> SWEDEN | AV11: {=IF(SUMPRODUCT((LEN($D$40:$D$45)>0)*(LEN($E$40:$E$45)>0))=0,"",LARGE($AP$40:$AP$43,3)-5)} -> 1998023 | AW11: =IF(AV11="","",RANK(AV11,$AV$6:$AV$17,0)) -> 9
B12: CANADA | C12: BOSNIA H. | D12: 2 | E12: 1 | F12: 1B | G12: {=IF(SUMPRODUCT((LEN($D$12:$D$17)>0)*(LEN($E$12:$E$17)>0))=0,"",IFERROR(INDEX($AN$12:$AN$15,MATCH(LARGE($AP$12:$AP$15,1),$AP$12:$AP$15,0)),""))} -> CANADA | H12: {=IF(SUMPRODUCT((LEN($D$12:$D$17)>0)*(LEN($E$12:$E$17)>0))=0,"",IFERROR(INDEX($AO$12:$AO$15,MATCH(LARGE($AP$12:$AP$15,1),$AP$12:$AP$15,0)),""))} -> 7 | T12: Q2 | U12: =IF(Q15="","",IF(Q15=1, P15, P16)) -> NETHERLANDS | AN12: =B12 -> CANADA | AO12: {=3*SUMPRODUCT(($B$12:$B$17=AN12)*($D$12:$D$17>$E$12:$E$17))+3*SUMPRODUCT(($C$12:$C$17=AN12)*($E$12:$E$17>$D$12:$D$17))+SUMPRODUCT((($B$12:$B$17=AN12)+($C$12:$C$17=AN12))*($D$12:$D$17=$E$12:$E$17)*(LEN($D$12:$D$17)>0))} -> 7 | AP12: =AO12*1000000+(AQ12-AR12)*1000+AQ12*10-0 -> 7003070 | AQ12: {=SUMPRODUCT(($B$12:$B$17=AN12)*$D$12:$D$17)+SUMPRODUCT(($C$12:$C$17=AN12)*$E$12:$E$17)} -> 7 | AR12: {=SUMPRODUCT(($B$12:$B$17=AN12)*$E$12:$E$17)+SUMPRODUCT(($C$12:$C$17=AN12)*$D$12:$D$17)} -> 4 | AT12: 3G | AU12: =_xlfn.XLOOKUP(AT12,$F$5:$F$85,$G$5:$G$85,"") -> IRAN | AV12: {=IF(SUMPRODUCT((LEN($D$47:$D$52)>0)*(LEN($E$47:$E$52)>0))=0,"",LARGE($AP$47:$AP$50,3)-6)} -> 3999002 | AW12: =IF(AV12="","",RANK(AV12,$AV$6:$AV$17,0)) -> 5
B13: QATAR | C13: SWITZERLAND | D13: 0 | E13: 3 | F13: 2B | G13: {=IF(SUMPRODUCT((LEN($D$12:$D$17)>0)*(LEN($E$12:$E$17)>0))=0,"",IFERROR(INDEX($AN$12:$AN$15,MATCH(LARGE($AP$12:$AP$15,2),$AP$12:$AP$15,0)),""))} -> SWITZERLAND | H13: {=IF(SUMPRODUCT((LEN($D$12:$D$17)>0)*(LEN($E$12:$E$17)>0))=0,"",IFERROR(INDEX($AO$12:$AO$15,MATCH(LARGE($AP$12:$AP$15,2),$AP$12:$AP$15,0)),""))} -> 5 | J13: 2A | K13: =_xlfn.XLOOKUP(J13,$F$5:$F$85,$G$5:$G$85, "") -> CZECHIA | L13: 2 | M13: T3 | AN13: =C12 -> BOSNIA H. | AO13: {=3*SUMPRODUCT(($B$12:$B$17=AN13)*($D$12:$D$17>$E$12:$E$17))+3*SUMPRODUCT(($C$12:$C$17=AN13)*($E$12:$E$17>$D$12:$D$17))+SUMPRODUCT((($B$12:$B$17=AN13)+($C$12:$C$17=AN13))*($D$12:$D$17=$E$12:$E$17)*(LEN($D$12:$D$17)>0))} -> 4 | AP13: =AO13*1000000+(AQ13-AR13)*1000+AQ13*10-1 -> 4000029 | AQ13: {=SUMPRODUCT(($B$12:$B$17=AN13)*$D$12:$D$17)+SUMPRODUCT(($C$12:$C$17=AN13)*$E$12:$E$17)} -> 3 | AR13: {=SUMPRODUCT(($B$12:$B$17=AN13)*$E$12:$E$17)+SUMPRODUCT(($C$12:$C$17=AN13)*$D$12:$D$17)} -> 3 | AT13: 3H | AU13: =_xlfn.XLOOKUP(AT13,$F$5:$F$85,$G$5:$G$85,"") -> SAUDI ARABIA | AV13: {=IF(SUMPRODUCT((LEN($D$54:$D$59)>0)*(LEN($E$54:$E$59)>0))=0,"",LARGE($AP$54:$AP$57,3)-7)} -> 995011 | AW13: =IF(AV13="","",RANK(AV13,$AV$6:$AV$17,0)) -> 12
B14: SWITZERLAND | C14: BOSNIA H. | D14: 1 | E14: 1 | F14: 3B | G14: {=IF(SUMPRODUCT((LEN($D$12:$D$17)>0)*(LEN($E$12:$E$17)>0))=0,"",IFERROR(INDEX($AN$12:$AN$15,MATCH(LARGE($AP$12:$AP$15,3),$AP$12:$AP$15,0)),""))} -> BOSNIA H. | H14: {=IF(SUMPRODUCT((LEN($D$12:$D$17)>0)*(LEN($E$12:$E$17)>0))=0,"",IFERROR(INDEX($AO$12:$AO$15,MATCH(LARGE($AP$12:$AP$15,3),$AP$12:$AP$15,0)),""))} -> 4 | J14: 2B | K14: =_xlfn.XLOOKUP(J14,$F$5:$F$85,$G$5:$G$85, "") -> SWITZERLAND | AN14: =B13 -> QATAR | AO14: {=3*SUMPRODUCT(($B$12:$B$17=AN14)*($D$12:$D$17>$E$12:$E$17))+3*SUMPRODUCT(($C$12:$C$17=AN14)*($E$12:$E$17>$D$12:$D$17))+SUMPRODUCT((($B$12:$B$17=AN14)+($C$12:$C$17=AN14))*($D$12:$D$17=$E$12:$E$17)*(LEN($D$12:$D$17)>0))} -> 0 | AP14: =AO14*1000000+(AQ14-AR14)*1000+AQ14*10-2 -> -5992 | AQ14: {=SUMPRODUCT(($B$12:$B$17=AN14)*$D$12:$D$17)+SUMPRODUCT(($C$12:$C$17=AN14)*$E$12:$E$17)} -> 1 | AR14: {=SUMPRODUCT(($B$12:$B$17=AN14)*$E$12:$E$17)+SUMPRODUCT(($C$12:$C$17=AN14)*$D$12:$D$17)} -> 7 | AT14: 3I | AU14: =_xlfn.XLOOKUP(AT14,$F$5:$F$85,$G$5:$G$85,"") -> SENEGAL | AV14: {=IF(SUMPRODUCT((LEN($D$61:$D$66)>0)*(LEN($E$61:$E$66)>0))=0,"",LARGE($AP$61:$AP$64,3)-8)} -> 4001041 | AW14: =IF(AV14="","",RANK(AV14,$AV$6:$AV$17,0)) -> 1
B15: CANADA | C15: QATAR | D15: 3 | E15: 1 | F15: 4B | G15: {=IF(SUMPRODUCT((LEN($D$12:$D$17)>0)*(LEN($E$12:$E$17)>0))=0,"",IFERROR(INDEX($AN$12:$AN$15,MATCH(LARGE($AP$12:$AP$15,4),$AP$12:$AP$15,0)),""))} -> QATAR | H15: {=IF(SUMPRODUCT((LEN($D$12:$D$17)>0)*(LEN($E$12:$E$17)>0))=0,"",IFERROR(INDEX($AO$12:$AO$15,MATCH(LARGE($AP$12:$AP$15,4),$AP$12:$AP$15,0)),""))} -> 0 | O15: T3 | P15: =IF(L13="","",IF(L13=1, K13, K14)) -> SWITZERLAND | Q15: 2 | R15: Q2 | AN15: =C13 -> SWITZERLAND | AO15: {=3*SUMPRODUCT(($B$12:$B$17=AN15)*($D$12:$D$17>$E$12:$E$17))+3*SUMPRODUCT(($C$12:$C$17=AN15)*($E$12:$E$17>$D$12:$D$17))+SUMPRODUCT((($B$12:$B$17=AN15)+($C$12:$C$17=AN15))*($D$12:$D$17=$E$12:$E$17)*(LEN($D$12:$D$17)>0))} -> 5 | AP15: =AO15*1000000+(AQ15-AR15)*1000+AQ15*10-3 -> 5003057 | AQ15: {=SUMPRODUCT(($B$12:$B$17=AN15)*$D$12:$D$17)+SUMPRODUCT(($C$12:$C$17=AN15)*$E$12:$E$17)} -> 6 | AR15: {=SUMPRODUCT(($B$12:$B$17=AN15)*$E$12:$E$17)+SUMPRODUCT(($C$12:$C$17=AN15)*$D$12:$D$17)} -> 3 | AT15: 3J | AU15: =_xlfn.XLOOKUP(AT15,$F$5:$F$85,$G$5:$G$85,"") -> AUSTRIA | AV15: {=IF(SUMPRODUCT((LEN($D$68:$D$73)>0)*(LEN($E$68:$E$73)>0))=0,"",LARGE($AP$68:$AP$71,3)-9)} -> 1999009 | AW15: =IF(AV15="","",RANK(AV15,$AV$6:$AV$17,0)) -> 8
B16: SWITZERLAND | C16: CANADA | D16: 2 | E16: 2 | O16: T4 | P16: =IF(L17="","",IF(L17=1, K17, K18)) -> NETHERLANDS | AT16: 3K | AU16: =_xlfn.XLOOKUP(AT16,$F$5:$F$85,$G$5:$G$85,"") -> DR CONGO | AV16: {=IF(SUMPRODUCT((LEN($D$75:$D$80)>0)*(LEN($E$75:$E$80)>0))=0,"",LARGE($AP$75:$AP$78,3)-10)} -> 2998019 | AW16: =IF(AV16="","",RANK(AV16,$AV$6:$AV$17,0)) -> 7
B17: BOSNIA H. | C17: QATAR | D17: 1 | E17: 0 | J17: 1F | K17: =_xlfn.XLOOKUP(J17,$F$5:$F$85,$G$5:$G$85, "") -> NETHERLANDS | L17: 1 | M17: T4 | AT17: 3L | AU17: =_xlfn.XLOOKUP(AT17,$F$5:$F$85,$G$5:$G$85,"") -> GHANA | AV17: {=IF(SUMPRODUCT((LEN($D$82:$D$87)>0)*(LEN($E$82:$E$87)>0))=0,"",LARGE($AP$82:$AP$85,3)-11)} -> 997007 | AW17: =IF(AV17="","",RANK(AV17,$AV$6:$AV$17,0)) -> 11
B18: GROUP C | J18: 2C | K18: =_xlfn.XLOOKUP(J18,$F$5:$F$85,$G$5:$G$85, "") -> SCOTLAND
B19: BRAZIL | C19: MOROCCO | D19: 4 | E19: 2 | F19: 1C | G19: {=IF(SUMPRODUCT((LEN($D$19:$D$24)>0)*(LEN($E$19:$E$24)>0))=0,"",IFERROR(INDEX($AN$19:$AN$22,MATCH(LARGE($AP$19:$AP$22,1),$AP$19:$AP$22,0)),""))} -> BRAZIL | H19: {=IF(SUMPRODUCT((LEN($D$19:$D$24)>0)*(LEN($E$19:$E$24)>0))=0,"",IFERROR(INDEX($AO$19:$AO$22,MATCH(LARGE($AP$19:$AP$22,1),$AP$19:$AP$22,0)),""))} -> 9 | Y19: S1 | Z19: =IF(V11="","",IF(V11=1, U11, U12)) -> FRANCE | AA19: 1 | AB19: F1 | AN19: =B19 -> BRAZIL | AO19: {=3*SUMPRODUCT(($B$19:$B$24=AN19)*($D$19:$D$24>$E$19:$E$24))+3*SUMPRODUCT(($C$19:$C$24=AN19)*($E$19:$E$24>$D$19:$D$24))+SUMPRODUCT((($B$19:$B$24=AN19)+($C$19:$C$24=AN19))*($D$19:$D$24=$E$19:$E$24)*(LEN($D$19:$D$24)>0))} -> 9 | AP19: =AO19*1000000+(AQ19-AR19)*1000+AQ19*10-0 -> 9006090 | AQ19: {=SUMPRODUCT(($B$19:$B$24=AN19)*$D$19:$D$24)+SUMPRODUCT(($C$19:$C$24=AN19)*$E$19:$E$24)} -> 9 | AR19: {=SUMPRODUCT(($B$19:$B$24=AN19)*$E$19:$E$24)+SUMPRODUCT(($C$19:$C$24=AN19)*$D$19:$D$24)} -> 3 | AT19: QUALIFYING KEY
B20: HAITI | C20: SCOTLAND | D20: 0 | E20: 2 | F20: 2C | G20: {=IF(SUMPRODUCT((LEN($D$19:$D$24)>0)*(LEN($E$19:$E$24)>0))=0,"",IFERROR(INDEX($AN$19:$AN$22,MATCH(LARGE($AP$19:$AP$22,2),$AP$19:$AP$22,0)),""))} -> SCOTLAND | H20: {=IF(SUMPRODUCT((LEN($D$19:$D$24)>0)*(LEN($E$19:$E$24)>0))=0,"",IFERROR(INDEX($AO$19:$AO$22,MATCH(LARGE($AP$19:$AP$22,2),$AP$19:$AP$22,0)),""))} -> 4 | Y20: S2 | Z20: =IF(V27="","",IF(V27=1, U27, U28)) -> SPAIN | AN20: =C19 -> MOROCCO | AO20: {=3*SUMPRODUCT(($B$19:$B$24=AN20)*($D$19:$D$24>$E$19:$E$24))+3*SUMPRODUCT(($C$19:$C$24=AN20)*($E$19:$E$24>$D$19:$D$24))+SUMPRODUCT((($B$19:$B$24=AN20)+($C$19:$C$24=AN20))*($D$19:$D$24=$E$19:$E$24)*(LEN($D$19:$D$24)>0))} -> 4 | AP20: =AO20*1000000+(AQ20-AR20)*1000+AQ20*10-1 -> 4000069 | AQ20: {=SUMPRODUCT(($B$19:$B$24=AN20)*$D$19:$D$24)+SUMPRODUCT(($C$19:$C$24=AN20)*$E$19:$E$24)} -> 7 | AR20: {=SUMPRODUCT(($B$19:$B$24=AN20)*$E$19:$E$24)+SUMPRODUCT(($C$19:$C$24=AN20)*$D$19:$D$24)} -> 7 | AT20: =IF(COUNT($AW$6:$AW$17)<12,"",_xlfn.TEXTJOIN("",TRUE,IF(N($AW6)>0,IF($AW6<=8,"A",""),""),IF(N($AW7)>0,IF($AW7<=8,"B",""),""),IF(N($AW8)>0,IF($AW8<=8,"C",""),""),IF(N($AW9)>0,IF($AW9<=8,"D",""),""),IF(N($AW10)>0,IF($AW10<=8,"E",""),""),IF(N($AW11)>0,IF($AW11<=8,"F",""),""),IF(N($AW12)>0,IF($AW12<=8,"G",""),""),IF(N($AW13)>0,IF($AW13<=8,"H",""),""),IF(N($AW14)>0,IF($AW14<=8,"I",""),""),IF(N($AW15)>0,IF($AW15<=8,"J",""),""),IF(N($AW16)>0,IF($AW16<=8,"K",""),""),IF(N($AW17)>0,IF($AW17<=8,"L",""),""))) -> ABCEGIJK
B21: SCOTLAND | C21: MOROCCO | D21: 2 | E21: 2 | F21: 3C | G21: {=IF(SUMPRODUCT((LEN($D$19:$D$24)>0)*(LEN($E$19:$E$24)>0))=0,"",IFERROR(INDEX($AN$19:$AN$22,MATCH(LARGE($AP$19:$AP$22,3),$AP$19:$AP$22,0)),""))} -> MOROCCO | H21: {=IF(SUMPRODUCT((LEN($D$19:$D$24)>0)*(LEN($E$19:$E$24)>0))=0,"",IFERROR(INDEX($AO$19:$AO$22,MATCH(LARGE($AP$19:$AP$22,3),$AP$19:$AP$22,0)),""))} -> 4 | J21: 2K | K21: =_xlfn.XLOOKUP(J21,$F$5:$F$85,$G$5:$G$85, "") -> COLOMBIA | L21: 1 | M21: T5 | AN21: =B20 -> HAITI | AO21: {=3*SUMPRODUCT(($B$19:$B$24=AN21)*($D$19:$D$24>$E$19:$E$24))+3*SUMPRODUCT(($C$19:$C$24=AN21)*($E$19:$E$24>$D$19:$D$24))+SUMPRODUCT((($B$19:$B$24=AN21)+($C$19:$C$24=AN21))*($D$19:$D$24=$E$19:$E$24)*(LEN($D$19:$D$24)>0))} -> 0 | AP21: =AO21*1000000+(AQ21-AR21)*1000+AQ21*10-2 -> -6992 | AQ21: {=SUMPRODUCT(($B$19:$B$24=AN21)*$D$19:$D$24)+SUMPRODUCT(($C$19:$C$24=AN21)*$E$19:$E$24)} -> 1 | AR21: {=SUMPRODUCT(($B$19:$B$24=AN21)*$E$19:$E$24)+SUMPRODUCT(($C$19:$C$24=AN21)*$D$19:$D$24)} -> 8
B22: BRAZIL | C22: HAITI | D22: 3 | E22: 0 | F22: 4C | G22: {=IF(SUMPRODUCT((LEN($D$19:$D$24)>0)*(LEN($E$19:$E$24)>0))=0,"",IFERROR(INDEX($AN$19:$AN$22,MATCH(LARGE($AP$19:$AP$22,4),$AP$19:$AP$22,0)),""))} -> HAITI | H22: {=IF(SUMPRODUCT((LEN($D$19:$D$24)>0)*(LEN($E$19:$E$24)>0))=0,"",IFERROR(INDEX($AO$19:$AO$22,MATCH(LARGE($AP$19:$AP$22,4),$AP$19:$AP$22,0)),""))} -> 0 | J22: 2L | K22: =_xlfn.XLOOKUP(J22,$F$5:$F$85,$G$5:$G$85, "") -> CROATIA | AN22: =C20 -> SCOTLAND | AO22: {=3*SUMPRODUCT(($B$19:$B$24=AN22)*($D$19:$D$24>$E$19:$E$24))+3*SUMPRODUCT(($C$19:$C$24=AN22)*($E$19:$E$24>$D$19:$D$24))+SUMPRODUCT((($B$19:$B$24=AN22)+($C$19:$C$24=AN22))*($D$19:$D$24=$E$19:$E$24)*(LEN($D$19:$D$24)>0))} -> 4 | AP22: =AO22*1000000+(AQ22-AR22)*1000+AQ22*10-3 -> 4001047 | AQ22: {=SUMPRODUCT(($B$19:$B$24=AN22)*$D$19:$D$24)+SUMPRODUCT(($C$19:$C$24=AN22)*$E$19:$E$24)} -> 5 | AR22: {=SUMPRODUCT(($B$19:$B$24=AN22)*$E$19:$E$24)+SUMPRODUCT(($C$19:$C$24=AN22)*$D$19:$D$24)} -> 4 | AT22: SLOT | AU22: 3RD ASSIGNED
B23: SCOTLAND | C23: BRAZIL | D23: 1 | E23: 2 | O23: T5 | P23: =IF(L21="","",IF(L21=1, K21, K22)) -> COLOMBIA | Q23: 2 | R23: Q3 | AT23: 1A | AU23: =IF($AT$20="","",IFERROR(VLOOKUP($AT$20,Terze!$B$2:$J$496,2,FALSE),"")) -> 3E
B24: MOROCCO | C24: HAITI | D24: 3 | E24: 1 | O24: T6 | P24: =IF(L25="","",IF(L25=1, K25, K26)) -> SPAIN | AT24: 1B | AU24: =IF($AT$20="","",IFERROR(VLOOKUP($AT$20,Terze!$B$2:$J$496,3,FALSE),"")) -> 3J
B25: GROUP D | J25: 1H | K25: =_xlfn.XLOOKUP(J25,$F$5:$F$85,$G$5:$G$85, "") -> SPAIN | L25: 1 | M25: T6 | AT25: 1D | AU25: =IF($AT$20="","",IFERROR(VLOOKUP($AT$20,Terze!$B$2:$J$496,4,FALSE),"")) -> 3B
B26: USA | C26: PARAGUAY | D26: 2 | E26: 0 | F26: 1D | G26: {=IF(SUMPRODUCT((LEN($D$26:$D$31)>0)*(LEN($E$26:$E$31)>0))=0,"",IFERROR(INDEX($AN$26:$AN$29,MATCH(LARGE($AP$26:$AP$29,1),$AP$26:$AP$29,0)),""))} -> TURKEY | H26: {=IF(SUMPRODUCT((LEN($D$26:$D$31)>0)*(LEN($E$26:$E$31)>0))=0,"",IFERROR(INDEX($AO$26:$AO$29,MATCH(LARGE($AP$26:$AP$29,1),$AP$26:$AP$29,0)),""))} -> 9 | J26: 2J | K26: =_xlfn.XLOOKUP(J26,$F$5:$F$85,$G$5:$G$85, "") -> ALGERIA | AN26: =B26 -> USA | AO26: {=3*SUMPRODUCT(($B$26:$B$31=AN26)*($D$26:$D$31>$E$26:$E$31))+3*SUMPRODUCT(($C$26:$C$31=AN26)*($E$26:$E$31>$D$26:$D$31))+SUMPRODUCT((($B$26:$B$31=AN26)+($C$26:$C$31=AN26))*($D$26:$D$31=$E$26:$E$31)*(LEN($D$26:$D$31)>0))} -> 6 | AP26: =AO26*1000000+(AQ26-AR26)*1000+AQ26*10-0 -> 6002040 | AQ26: {=SUMPRODUCT(($B$26:$B$31=AN26)*$D$26:$D$31)+SUMPRODUCT(($C$26:$C$31=AN26)*$E$26:$E$31)} -> 4 | AR26: {=SUMPRODUCT(($B$26:$B$31=AN26)*$E$26:$E$31)+SUMPRODUCT(($C$26:$C$31=AN26)*$D$26:$D$31)} -> 2 | AT26: 1E | AU26: =IF($AT$20="","",IFERROR(VLOOKUP($AT$20,Terze!$B$2:$J$496,5,FALSE),"")) -> 3C
B27: AUSTRALIA | C27: TURKEY | D27: 1 | E27: 3 | F27: 2D | G27: {=IF(SUMPRODUCT((LEN($D$26:$D$31)>0)*(LEN($E$26:$E$31)>0))=0,"",IFERROR(INDEX($AN$26:$AN$29,MATCH(LARGE($AP$26:$AP$29,2),$AP$26:$AP$29,0)),""))} -> USA | H27: {=IF(SUMPRODUCT((LEN($D$26:$D$31)>0)*(LEN($E$26:$E$31)>0))=0,"",IFERROR(INDEX($AO$26:$AO$29,MATCH(LARGE($AP$26:$AP$29,2),$AP$26:$AP$29,0)),""))} -> 6 | T27: Q3 | U27: =IF(Q23="","",IF(Q23=1, P23, P24)) -> SPAIN | V27: 1 | W27: S2 | AN27: =C26 -> PARAGUAY | AO27: {=3*SUMPRODUCT(($B$26:$B$31=AN27)*($D$26:$D$31>$E$26:$E$31))+3*SUMPRODUCT(($C$26:$C$31=AN27)*($E$26:$E$31>$D$26:$D$31))+SUMPRODUCT((($B$26:$B$31=AN27)+($C$26:$C$31=AN27))*($D$26:$D$31=$E$26:$E$31)*(LEN($D$26:$D$31)>0))} -> 1 | AP27: =AO27*1000000+(AQ27-AR27)*1000+AQ27*10-1 -> 997009 | AQ27: {=SUMPRODUCT(($B$26:$B$31=AN27)*$D$26:$D$31)+SUMPRODUCT(($C$26:$C$31=AN27)*$E$26:$E$31)} -> 1 | AR27: {=SUMPRODUCT(($B$26:$B$31=AN27)*$E$26:$E$31)+SUMPRODUCT(($C$26:$C$31=AN27)*$D$26:$D$31)} -> 4 | AT27: 1G | AU27: =IF($AT$20="","",IFERROR(VLOOKUP($AT$20,Terze!$B$2:$J$496,6,FALSE),"")) -> 3A
B28: USA | C28: AUSTRALIA | D28: 1 | E28: 0 | F28: 3D | G28: {=IF(SUMPRODUCT((LEN($D$26:$D$31)>0)*(LEN($E$26:$E$31)>0))=0,"",IFERROR(INDEX($AN$26:$AN$29,MATCH(LARGE($AP$26:$AP$29,3),$AP$26:$AP$29,0)),""))} -> AUSTRALIA | H28: {=IF(SUMPRODUCT((LEN($D$26:$D$31)>0)*(LEN($E$26:$E$31)>0))=0,"",IFERROR(INDEX($AO$26:$AO$29,MATCH(LARGE($AP$26:$AP$29,3),$AP$26:$AP$29,0)),""))} -> 1 | T28: Q4 | U28: =IF(Q31="","",IF(Q31=1, P31, P32)) -> TURKEY | AN28: =B27 -> AUSTRALIA | AO28: {=3*SUMPRODUCT(($B$26:$B$31=AN28)*($D$26:$D$31>$E$26:$E$31))+3*SUMPRODUCT(($C$26:$C$31=AN28)*($E$26:$E$31>$D$26:$D$31))+SUMPRODUCT((($B$26:$B$31=AN28)+($C$26:$C$31=AN28))*($D$26:$D$31=$E$26:$E$31)*(LEN($D$26:$D$31)>0))} -> 1 | AP28: =AO28*1000000+(AQ28-AR28)*1000+AQ28*10-2 -> 997018 | AQ28: {=SUMPRODUCT(($B$26:$B$31=AN28)*$D$26:$D$31)+SUMPRODUCT(($C$26:$C$31=AN28)*$E$26:$E$31)} -> 2 | AR28: {=SUMPRODUCT(($B$26:$B$31=AN28)*$E$26:$E$31)+SUMPRODUCT(($C$26:$C$31=AN28)*$D$26:$D$31)} -> 5 | AT28: 1I | AU28: =IF($AT$20="","",IFERROR(VLOOKUP($AT$20,Terze!$B$2:$J$496,7,FALSE),"")) -> 3G
B29: TURKEY | C29: PARAGUAY | D29: 1 | E29: 0 | F29: 4D | G29: {=IF(SUMPRODUCT((LEN($D$26:$D$31)>0)*(LEN($E$26:$E$31)>0))=0,"",IFERROR(INDEX($AN$26:$AN$29,MATCH(LARGE($AP$26:$AP$29,4),$AP$26:$AP$29,0)),""))} -> PARAGUAY | H29: {=IF(SUMPRODUCT((LEN($D$26:$D$31)>0)*(LEN($E$26:$E$31)>0))=0,"",IFERROR(INDEX($AO$26:$AO$29,MATCH(LARGE($AP$26:$AP$29,4),$AP$26:$AP$29,0)),""))} -> 1 | J29: 1D | K29: =_xlfn.XLOOKUP(J29,$F$5:$F$85,$G$5:$G$85, "") -> TURKEY | L29: 1 | M29: T7 | AN29: =C27 -> TURKEY | AO29: {=3*SUMPRODUCT(($B$26:$B$31=AN29)*($D$26:$D$31>$E$26:$E$31))+3*SUMPRODUCT(($C$26:$C$31=AN29)*($E$26:$E$31>$D$26:$D$31))+SUMPRODUCT((($B$26:$B$31=AN29)+($C$26:$C$31=AN29))*($D$26:$D$31=$E$26:$E$31)*(LEN($D$26:$D$31)>0))} -> 9 | AP29: =AO29*1000000+(AQ29-AR29)*1000+AQ29*10-3 -> 9004057 | AQ29: {=SUMPRODUCT(($B$26:$B$31=AN29)*$D$26:$D$31)+SUMPRODUCT(($C$26:$C$31=AN29)*$E$26:$E$31)} -> 6 | AR29: {=SUMPRODUCT(($B$26:$B$31=AN29)*$E$26:$E$31)+SUMPRODUCT(($C$26:$C$31=AN29)*$D$26:$D$31)} -> 2 | AT29: 1K | AU29: =IF($AT$20="","",IFERROR(VLOOKUP($AT$20,Terze!$B$2:$J$496,8,FALSE),"")) -> 3I
B30: TURKEY | C30: USA | D30: 2 | E30: 1 | J30: =AU25 -> 3B | K30: =_xlfn.XLOOKUP(J30,$F$5:$F$85,$G$5:$G$85, "") -> BOSNIA H. | AT30: 1L | AU30: =IF($AT$20="","",IFERROR(VLOOKUP($AT$20,Terze!$B$2:$J$496,9,FALSE),"")) -> 3K
B31: PARAGUAY | C31: AUSTRALIA | D31: 1 | E31: 1 | O31: T7 | P31: =IF(L29="","",IF(L29=1, K29, K30)) -> TURKEY | Q31: 1 | R31: Q4
B32: GROUP E | O32: T8 | P32: =IF(L33="","",IF(L33=1, K33, K34)) -> BELGIUM
B33: GERMANY | C33: CURAÇAO | D33: 5 | E33: 0 | F33: 1E | G33: {=IF(SUMPRODUCT((LEN($D$33:$D$38)>0)*(LEN($E$33:$E$38)>0))=0,"",IFERROR(INDEX($AN$33:$AN$36,MATCH(LARGE($AP$33:$AP$36,1),$AP$33:$AP$36,0)),""))} -> GERMANY | H33: {=IF(SUMPRODUCT((LEN($D$33:$D$38)>0)*(LEN($E$33:$E$38)>0))=0,"",IFERROR(INDEX($AO$33:$AO$36,MATCH(LARGE($AP$33:$AP$36,1),$AP$33:$AP$36,0)),""))} -> 7 | J33: 1G | K33: =_xlfn.XLOOKUP(J33,$F$5:$F$85,$G$5:$G$85, "") -> BELGIUM | L33: 1 | M33: T8 | AN33: =B33 -> GERMANY | AO33: {=3*SUMPRODUCT(($B$33:$B$38=AN33)*($D$33:$D$38>$E$33:$E$38))+3*SUMPRODUCT(($C$33:$C$38=AN33)*($E$33:$E$38>$D$33:$D$38))+SUMPRODUCT((($B$33:$B$38=AN33)+($C$33:$C$38=AN33))*($D$33:$D$38=$E$33:$E$38)*(LEN($D$33:$D$38)>0))} -> 7 | AP33: =AO33*1000000+(AQ33-AR33)*1000+AQ33*10-0 -> 7006090 | AQ33: {=SUMPRODUCT(($B$33:$B$38=AN33)*$D$33:$D$38)+SUMPRODUCT(($C$33:$C$38=AN33)*$E$33:$E$38)} -> 9 | AR33: {=SUMPRODUCT(($B$33:$B$38=AN33)*$E$33:$E$38)+SUMPRODUCT(($C$33:$C$38=AN33)*$D$33:$D$38)} -> 3
B34: IVORY COAST | C34: ECUADOR | D34: 1 | E34: 2 | F34: 2E | G34: {=IF(SUMPRODUCT((LEN($D$33:$D$38)>0)*(LEN($E$33:$E$38)>0))=0,"",IFERROR(INDEX($AN$33:$AN$36,MATCH(LARGE($AP$33:$AP$36,2),$AP$33:$AP$36,0)),""))} -> ECUADOR | H34: {=IF(SUMPRODUCT((LEN($D$33:$D$38)>0)*(LEN($E$33:$E$38)>0))=0,"",IFERROR(INDEX($AO$33:$AO$36,MATCH(LARGE($AP$33:$AP$36,2),$AP$33:$AP$36,0)),""))} -> 7 | J34: =AU27 -> 3A | K34: =_xlfn.XLOOKUP(J34,$F$5:$F$85,$G$5:$G$85, "") -> SOUTH KOREA | AN34: =C33 -> CURAÇAO | AO34: {=3*SUMPRODUCT(($B$33:$B$38=AN34)*($D$33:$D$38>$E$33:$E$38))+3*SUMPRODUCT(($C$33:$C$38=AN34)*($E$33:$E$38>$D$33:$D$38))+SUMPRODUCT((($B$33:$B$38=AN34)+($C$33:$C$38=AN34))*($D$33:$D$38=$E$33:$E$38)*(LEN($D$33:$D$38)>0))} -> 0 | AP34: =AO34*1000000+(AQ34-AR34)*1000+AQ34*10-1 -> -8991 | AQ34: {=SUMPRODUCT(($B$33:$B$38=AN34)*$D$33:$D$38)+SUMPRODUCT(($C$33:$C$38=AN34)*$E$33:$E$38)} -> 1 | AR34: {=SUMPRODUCT(($B$33:$B$38=AN34)*$E$33:$E$38)+SUMPRODUCT(($C$33:$C$38=AN34)*$D$33:$D$38)} -> 10
B35: GERMANY | C35: IVORY COAST | D35: 2 | E35: 1 | F35: 3E | G35: {=IF(SUMPRODUCT((LEN($D$33:$D$38)>0)*(LEN($E$33:$E$38)>0))=0,"",IFERROR(INDEX($AN$33:$AN$36,MATCH(LARGE($AP$33:$AP$36,3),$AP$33:$AP$36,0)),""))} -> IVORY COAST | H35: {=IF(SUMPRODUCT((LEN($D$33:$D$38)>0)*(LEN($E$33:$E$38)>0))=0,"",IFERROR(INDEX($AO$33:$AO$36,MATCH(LARGE($AP$33:$AP$36,3),$AP$33:$AP$36,0)),""))} -> 3 | AD35: F1 | AE35: =IF(AA19="","",IF(AA19=1, Z19, Z20)) -> FRANCE | AF35: 2 | AG35: CW | AI35: 1° | AJ35: =IF(AF35="","",IF(AF35=1, AE35, AE36)) -> PORTUGAL | AN35: =B34 -> IVORY COAST | AO35: {=3*SUMPRODUCT(($B$33:$B$38=AN35)*($D$33:$D$38>$E$33:$E$38))+3*SUMPRODUCT(($C$33:$C$38=AN35)*($E$33:$E$38>$D$33:$D$38))+SUMPRODUCT((($B$33:$B$38=AN35)+($C$33:$C$38=AN35))*($D$33:$D$38=$E$33:$E$38)*(LEN($D$33:$D$38)>0))} -> 3 | AP35: =AO35*1000000+(AQ35-AR35)*1000+AQ35*10-2 -> 2999038 | AQ35: {=SUMPRODUCT(($B$33:$B$38=AN35)*$D$33:$D$38)+SUMPRODUCT(($C$33:$C$38=AN35)*$E$33:$E$38)} -> 4 | AR35: {=SUMPRODUCT(($B$33:$B$38=AN35)*$E$33:$E$38)+SUMPRODUCT(($C$33:$C$38=AN35)*$D$33:$D$38)} -> 5
B36: ECUADOR | C36: CURAÇAO | D36: 3 | E36: 0 | F36: 4E | G36: {=IF(SUMPRODUCT((LEN($D$33:$D$38)>0)*(LEN($E$33:$E$38)>0))=0,"",IFERROR(INDEX($AN$33:$AN$36,MATCH(LARGE($AP$33:$AP$36,4),$AP$33:$AP$36,0)),""))} -> CURAÇAO | H36: {=IF(SUMPRODUCT((LEN($D$33:$D$38)>0)*(LEN($E$33:$E$38)>0))=0,"",IFERROR(INDEX($AO$33:$AO$36,MATCH(LARGE($AP$33:$AP$36,4),$AP$33:$AP$36,0)),""))} -> 0 | AD36: F2 | AE36: =IF(AA51="","",IF(AA51=1, Z51, Z52)) -> PORTUGAL | AI36: 2° | AJ36: =IF(AF35="","",IF(AF35=2, AE35, AE36)) -> FRANCE | AN36: =C34 -> ECUADOR | AO36: {=3*SUMPRODUCT(($B$33:$B$38=AN36)*($D$33:$D$38>$E$33:$E$38))+3*SUMPRODUCT(($C$33:$C$38=AN36)*($E$33:$E$38>$D$33:$D$38))+SUMPRODUCT((($B$33:$B$38=AN36)+($C$33:$C$38=AN36))*($D$33:$D$38=$E$33:$E$38)*(LEN($D$33:$D$38)>0))} -> 7 | AP36: =AO36*1000000+(AQ36-AR36)*1000+AQ36*10-3 -> 7004067 | AQ36: {=SUMPRODUCT(($B$33:$B$38=AN36)*$D$33:$D$38)+SUMPRODUCT(($C$33:$C$38=AN36)*$E$33:$E$38)} -> 7 | AR36: {=SUMPRODUCT(($B$33:$B$38=AN36)*$E$33:$E$38)+SUMPRODUCT(($C$33:$C$38=AN36)*$D$33:$D$38)} -> 3
B37: CURAÇAO | C37: IVORY COAST | D37: 1 | E37: 2 | J37: 1C | K37: =_xlfn.XLOOKUP(J37,$F$5:$F$85,$G$5:$G$85, "") -> BRAZIL | L37: 1 | M37: T9 | AI37: 3° | AJ37: =IF(AF43="","",IF(AF43=1, AE43, AE44)) -> SPAIN
B38: ECUADOR | C38: GERMANY | D38: 2 | E38: 2 | J38: 2F | K38: =_xlfn.XLOOKUP(J38,$F$5:$F$85,$G$5:$G$85, "") -> JAPAN | AI38: 4° | AJ38: =IF(AF43="","",IF(AF43=2, AE43, AE44)) -> NORWAY
B39: GROUP F | O39: T9 | P39: =IF(L37="","",IF(L37=1, K37, K38)) -> BRAZIL | Q39: 2 | R39: Q5
B40: NETHERLANDS | C40: JAPAN | D40: 2 | E40: 2 | F40: 1F | G40: {=IF(SUMPRODUCT((LEN($D$40:$D$45)>0)*(LEN($E$40:$E$45)>0))=0,"",IFERROR(INDEX($AN$40:$AN$43,MATCH(LARGE($AP$40:$AP$43,1),$AP$40:$AP$43,0)),""))} -> NETHERLANDS | H40: {=IF(SUMPRODUCT((LEN($D$40:$D$45)>0)*(LEN($E$40:$E$45)>0))=0,"",IFERROR(INDEX($AO$40:$AO$43,MATCH(LARGE($AP$40:$AP$43,1),$AP$40:$AP$43,0)),""))} -> 7 | O40: T10 | P40: =IF(L41="","",IF(L41=1, K41, K42)) -> NORWAY | AD40: THIRD PLACE FINAL | AN40: =B40 -> NETHERLANDS | AO40: {=3*SUMPRODUCT(($B$40:$B$45=AN40)*($D$40:$D$45>$E$40:$E$45))+3*SUMPRODUCT(($C$40:$C$45=AN40)*($E$40:$E$45>$D$40:$D$45))+SUMPRODUCT((($B$40:$B$45=AN40)+($C$40:$C$45=AN40))*($D$40:$D$45=$E$40:$E$45)*(LEN($D$40:$D$45)>0))} -> 7 | AP40: =AO40*1000000+(AQ40-AR40)*1000+AQ40*10-0 -> 7004080 | AQ40: {=SUMPRODUCT(($B$40:$B$45=AN40)*$D$40:$D$45)+SUMPRODUCT(($C$40:$C$45=AN40)*$E$40:$E$45)} -> 8 | AR40: {=SUMPRODUCT(($B$40:$B$45=AN40)*$E$40:$E$45)+SUMPRODUCT(($C$40:$C$45=AN40)*$D$40:$D$45)} -> 4
B41: SWEDEN | C41: TUNISIA | D41: 1 | E41: 1 | F41: 2F | G41: {=IF(SUMPRODUCT((LEN($D$40:$D$45)>0)*(LEN($E$40:$E$45)>0))=0,"",IFERROR(INDEX($AN$40:$AN$43,MATCH(LARGE($AP$40:$AP$43,2),$AP$40:$AP$43,0)),""))} -> JAPAN | H41: {=IF(SUMPRODUCT((LEN($D$40:$D$45)>0)*(LEN($E$40:$E$45)>0))=0,"",IFERROR(INDEX($AO$40:$AO$43,MATCH(LARGE($AP$40:$AP$43,2),$AP$40:$AP$43,0)),""))} -> 5 | J41: 2E | K41: =_xlfn.XLOOKUP(J41,$F$5:$F$85,$G$5:$G$85, "") -> ECUADOR | L41: 2 | M41: T10 | AN41: =C40 -> JAPAN | AO41: {=3*SUMPRODUCT(($B$40:$B$45=AN41)*($D$40:$D$45>$E$40:$E$45))+3*SUMPRODUCT(($C$40:$C$45=AN41)*($E$40:$E$45>$D$40:$D$45))+SUMPRODUCT((($B$40:$B$45=AN41)+($C$40:$C$45=AN41))*($D$40:$D$45=$E$40:$E$45)*(LEN($D$40:$D$45)>0))} -> 5 | AP41: =AO41*1000000+(AQ41-AR41)*1000+AQ41*10-1 -> 5001049 | AQ41: {=SUMPRODUCT(($B$40:$B$45=AN41)*$D$40:$D$45)+SUMPRODUCT(($C$40:$C$45=AN41)*$E$40:$E$45)} -> 5 | AR41: {=SUMPRODUCT(($B$40:$B$45=AN41)*$E$40:$E$45)+SUMPRODUCT(($C$40:$C$45=AN41)*$D$40:$D$45)} -> 4
B42: NETHERLANDS | C42: SWEDEN | D42: 3 | E42: 1 | F42: 3F | G42: {=IF(SUMPRODUCT((LEN($D$40:$D$45)>0)*(LEN($E$40:$E$45)>0))=0,"",IFERROR(INDEX($AN$40:$AN$43,MATCH(LARGE($AP$40:$AP$43,3),$AP$40:$AP$43,0)),""))} -> SWEDEN | H42: {=IF(SUMPRODUCT((LEN($D$40:$D$45)>0)*(LEN($E$40:$E$45)>0))=0,"",IFERROR(INDEX($AO$40:$AO$43,MATCH(LARGE($AP$40:$AP$43,3),$AP$40:$AP$43,0)),""))} -> 2 | J42: 2I | K42: =_xlfn.XLOOKUP(J42,$F$5:$F$85,$G$5:$G$85, "") -> NORWAY | AI42: TOP SCORER | AN42: =B41 -> SWEDEN | AO42: {=3*SUMPRODUCT(($B$40:$B$45=AN42)*($D$40:$D$45>$E$40:$E$45))+3*SUMPRODUCT(($C$40:$C$45=AN42)*($E$40:$E$45>$D$40:$D$45))+SUMPRODUCT((($B$40:$B$45=AN42)+($C$40:$C$45=AN42))*($D$40:$D$45=$E$40:$E$45)*(LEN($D$40:$D$45)>0))} -> 2 | AP42: =AO42*1000000+(AQ42-AR42)*1000+AQ42*10-2 -> 1998028 | AQ42: {=SUMPRODUCT(($B$40:$B$45=AN42)*$D$40:$D$45)+SUMPRODUCT(($C$40:$C$45=AN42)*$E$40:$E$45)} -> 3 | AR42: {=SUMPRODUCT(($B$40:$B$45=AN42)*$E$40:$E$45)+SUMPRODUCT(($C$40:$C$45=AN42)*$D$40:$D$45)} -> 5
...

Sheet Terze
A1: No. | B1: Combo (gruppi qualificati) | C1: 1A vs | D1: 1B vs | E1: 1D vs | F1: 1E vs | G1: 1G vs | H1: 1I vs | I1: 1K vs | J1: 1L vs
A2: 1 | B2: EFGHIJKL | C2: 3E | D2: 3J | E2: 3I | F2: 3F | G2: 3H | H2: 3G | I2: 3L | J2: 3K
A3: 2 | B3: DFGHIJKL | C3: 3H | D3: 3G | E3: 3I | F3: 3D | G3: 3J | H3: 3F | I3: 3L | J3: 3K
A4: 3 | B4: DEGHIJKL | C4: 3E | D4: 3J | E4: 3I | F4: 3D | G4: 3H | H4: 3G | I4: 3L | J4: 3K
A5: 4 | B5: DEFHIJKL | C5: 3E | D5: 3J | E5: 3I | F5: 3D | G5: 3H | H5: 3F | I5: 3L | J5: 3K
A6: 5 | B6: DEFGIJKL | C6: 3E | D6: 3G | E6: 3I | F6: 3D | G6: 3J | H6: 3F | I6: 3L | J6: 3K
A7: 6 | B7: DEFGHJKL | C7: 3E | D7: 3G | E7: 3J | F7: 3D | G7: 3H | H7: 3F | I7: 3L | J7: 3K
A8: 7 | B8: DEFGHIKL | C8: 3E | D8: 3G | E8: 3I | F8: 3D | G8: 3H | H8: 3F | I8: 3L | J8: 3K
A9: 8 | B9: DEFGHIJL | C9: 3E | D9: 3G | E9: 3J | F9: 3D | G9: 3H | H9: 3F | I9: 3L | J9: 3I
A10: 9 | B10: DEFGHIJK | C10: 3E | D10: 3G | E10: 3J | F10: 3D | G10: 3H | H10: 3F | I10: 3I | J10: 3K
A11: 10 | B11: CFGHIJKL | C11: 3H | D11: 3G | E11: 3I | F11: 3C | G11: 3J | H11: 3F | I11: 3L | J11: 3K
A12: 11 | B12: CEGHIJKL | C12: 3E | D12: 3J | E12: 3I | F12: 3C | G12: 3H | H12: 3G | I12: 3L | J12: 3K
A13: 12 | B13: CEFHIJKL | C13: 3E | D13: 3J | E13: 3I | F13: 3C | G13: 3H | H13: 3F | I13: 3L | J13: 3K
... A496: 495 | B496: ABCDEFGH | C496: 3H | D496: 3G | E496: 3B | F496: 3C | G496: 3A | H496: 3F | I496: 3D | J496: 3E
